Workbook

Sheet Cover
A1: UK major port freight traffic by cargo type and year (filter by direction and route) from 2000
A2: About this data
A3: Description: This table provides all traffic through UK major ports, for all cargo types by year from 2000, with filters for measure (tonnage, units or TEU), direction and route.
A4: Definitions: Bulk Fuels are cargo which is used for the production of energy, including liquefied gas, crude oil, oil products, coal Main Freight is a subset of unitised goods consisting of all containers and those Ro-Ro units designed to carry freight including all container (Lo-Lo) traffic, road goods vehicles and trailers, unaccompanied road goods vehicle trailers and rail wagons, shipborne trailers, barges engaged in goods transport. TEU (twenty-foot equivalent units) is a standardised measure to allow for the diferent sizes of container boxes. See the Notes and Definitions for a breakdown of the measure.
A5: Author: Maritime Statistics
A6: Source: Department for Transport: Port Freight Statistics
A7: Link to publication on GOV.UK: Port Freight Statistics Publication
A8: Last updated: July 2026
A9: Next update: Summer 2027
A10: The statistics presented in this spreadsheet were independently reviewed by the Office for Statistics Regulation in December 2018 and are therefore labelled ‘accredited official statistics’
A11: Contact
A12: maritime.stats@dft.gov.uk
... A15: Technical Note

Sheet Contents
A1: Table of contents
A2: This worksheet contains 1 table.
A3: Worksheet name | B3: Worksheet description
A4: PORT0201 | B4: This table provides all traffic through UK major ports, for all cargo types by year from 2000, with filters for measure (tonnage, units or TEU), direction and route.
A5: Notes | B5: A table of notes and caveats used in the tables.

Sheet port0201
A1: Table PORT0201: UK major port freight traffic by cargo type and year (filter by direction and route) from 2000
A2: To view the data in this table, you will need to 'enable editing'. You can either click on the yellow banner at the top or use F2 and select enable content.
A3: This worksheet contains one table and formulas are used in the table, to see the underlying data use the "Data" sheet. Notes are used throughout, please see the notes tab to find the related note text.
A4: The figures in this table are in thousand tonnes or thousand units. Displayed figures might not sum up to the displayed totals due to rounding.
A5: Some shorthand is used in this table. "0" is absolute zero, "z" is not applicable, "LOW" means the figure is less than half of the smallest unit displayed and [r] is where the datapoint has been revised since the last release.
A6: Filters are used throughout this table. The drop-down menus are available in cell B7, B8 and B9, to use the filter, select the cell, then either click on the arrow and select the value or hold alt and the down arrow then use the left and right arrows to select the value.
A7: Direction | B7: Both Directions
A8: Metric | B8: Tonnage
A9: Type of Route [Note 1] | B9: All Routes
A10: Cargo Group | B10: Cargo Category | C10: 2000 | D10: 2001 | E10: 2002 | F10: 2003 | G10: 2004 | H10: 2005 | I10: 2006 | J10: 2007 | K10: 2008 | L10: 2009 | M10: 2010 | N10: 2011 | O10: 2012 | P10: 2013 | Q10: 2014 | R10: 2015 | S10: 2016 | T10: 2017 | U10: 2018 | V10: 2019 [Note 5, 6] | W10: 2020 [Note 4, 6] | X10: 2021 [Note 6] | Y10: 2022 [Note 6] | Z10: 2023 [Note 6] | AA10: 2024 | AB10: 2025 [Note 7]
A11: Liquid Bulk | B11: Liquefied gas | C11: =Working!D6 -> 6499.735 | D11: =Working!E6 -> 8051.473 | E11: =Working!F6 -> 7850.18 | F11: =Working!G6 -> 7542.956 | G11: =Working!H6 -> 7410.348 | H11: =Working!I6 -> 7899.554 | I11: =Working!J6 -> 9470.601 | J11: =Working!K6 -> 7901.754 | ... AB11: =Working!AC6 -> 16954.295
A12: Liquid Bulk | B12: Crude oil | C12: =Working!D7 -> 184344.35 | D12: =Working!E7 -> 168557.06 | E12: =Working!F7 -> 172523.73 | F12: =Working!G7 -> 160318.89 | G12: =Working!H7 -> 161595.49 | H12: =Working!I7 -> 153498.95 | I12: =Working!J7 -> 142200.27 | J12: =Working!K7 -> 140131.86 | ... AB12: =Working!AC7 -> 62509.23
A13: Liquid Bulk | B13: Oil products | C13: =Working!D8 -> 86249.525 | D13: =Working!E8 -> 82592.958 | E13: =Working!F8 -> 78163.916 | F13: =Working!G8 -> 80351.013 | G13: =Working!H8 -> 85975.959 | H13: =Working!I8 -> 89000.682 | I13: =Working!J8 -> 85119.501 | J13: =Working!K8 -> 85960.272 | ... AB13: =Working!AC8 -> 72004.882
A14: Liquid Bulk | B14: Other liquid bulk products | C14: =Working!D9 -> 13456.65 | D14: =Working!E9 -> 14332.779 | E14: =Working!F9 -> 12257.988 | F14: =Working!G9 -> 12086.552 | G14: =Working!H9 -> 12451.715 | H14: =Working!I9 -> 12767.421 | I14: =Working!J9 -> 13597.769 | J14: =Working!K9 -> 14598.533 | ... AB14: =Working!AC9 -> 8519.245
A15: All liquid bulk | B15: All liquid bulk | C15: =Working!D10 -> 290550.26 | D15: =Working!E10 -> 273534.27 | E15: =Working!F10 -> 270795.81 | F15: =Working!G10 -> 260299.41 | G15: =Working!H10 -> 267433.51 | H15: =Working!I10 -> 263166.6 | I15: =Working!J10 -> 250388.14 | J15: =Working!K10 -> 248592.42 | ... AB15: =Working!AC10 -> 159987.65
A16: Dry Bulk | B16: Ores | C16: =Working!D11 -> 20318.624 | D16: =Working!E11 -> 19559.76 | E16: =Working!F11 -> 17009.198 | F16: =Working!G11 -> 17988.786 | G16: =Working!H11 -> 17826.584 | H16: =Working!I11 -> 17940.509 | I16: =Working!J11 -> 18300.511 | J16: =Working!K11 -> 19144.281 | ... AB16: =Working!AC11 -> 9963.657
A17: Dry Bulk | B17: Coal | C17: =Working!D12 -> 27830.277 | D17: =Working!E12 -> 39919.835 | E17: =Working!F12 -> 32998.074 | F17: =Working!G12 -> 37280.728 | G17: =Working!H12 -> 41315.997 | H17: =Working!I12 -> 51787.366 | I17: =Working!J12 -> 57281.96 | J17: =Working!K12 -> 47426.647 | ... AB17: =Working!AC12 -> 4358.873
A18: Dry Bulk | B18: Agricultural products | C18: =Working!D13 -> 14106.536 | D18: =Working!E13 -> 13026.302 | E18: =Working!F13 -> 13061.469 | F18: =Working!G13 -> 14751.974 | G18: =Working!H13 -> 12924.524 | H18: =Working!I13 -> 13607.652 | I18: =Working!J13 -> 13095.04 | J18: =Working!K13 -> 12745.616 | ... AB18: =Working!AC13 -> 10888.209
A19: Dry Bulk | B19: Wood pellets [Note 7] | C19: =Working!D14 -> 0 | D19: =Working!E14 -> 0 | E19: =Working!F14 -> 0 | F19: =Working!G14 -> 0 | G19: =Working!H14 -> 0 | H19: =Working!I14 -> 0 | I19: =Working!J14 -> 0 | J19: =Working!K14 -> 0 | ... AB19: =Working!AC14 -> 9935.277
A20: Dry Bulk | B20: Other dry bulk | C20: =Working!D15 -> 41347.061 | D20: =Working!E15 -> 42480.347 | E20: =Working!F15 -> 43673.663 | F20: =Working!G15 -> 44407.473 | G20: =Working!H15 -> 42122.459 | H20: =Working!I15 -> 42232.211 | I20: =Working!J15 -> 44402.503 | J20: =Working!K15 -> 46066.558 | ... AB20: =Working!AC15 -> 43589.871
A21: All dry bulk | B21: All dry bulk | C21: =Working!D16 -> 103602.5 | D21: =Working!E16 -> 114986.24 | E21: =Working!F16 -> 106742.4 | F21: =Working!G16 -> 114428.96 | G21: =Working!H16 -> 114189.56 | H21: =Working!I16 -> 125567.74 | I21: =Working!J16 -> 133080.01 | J21: =Working!K16 -> 125383.1 | ... AB21: =Working!AC16 -> 78735.887
A22: Container (Lo-Lo) traffic | B22: 20' containers | C22: =Working!D17 -> 23042.378 | D22: =Working!E17 -> 22156.339 | E22: =Working!F17 -> 19900.424 | F22: =Working!G17 -> 19855.484 | G22: =Working!H17 -> 21013.069 | H22: =Working!I17 -> 19678.151 | I22: =Working!J17 -> 18547.524 | J22: =Working!K17 -> 19087.891 | ... AB22: =Working!AC17 -> 17760.956
... A47: All main freight | B47: All main freight | C47: =Working!D42 -> 131231.61 | D47: =Working!E42 -> 128913.58 | E47: =Working!F42 -> 131308.24 | F47: =Working!G42 -> 131918.96 | G47: =Working!H42 -> 142518.23 | H47: =Working!I42 -> 147188.48 | I47: =Working!J42 -> 151254.74 | J47: =Working!K42 -> 157630.94 | ... AB47: =Working!AC42 -> 158100.7

Sheet Notes
A1: Notes table for PORT0201
A2: This worksheet contains 1 table.
A3: This sheet includes information relevant to the data in these tables. Corresponding note numbers are labelled where relevant in the data tables.
A4: Note number | B4: Note text
A5: Note 1 | B5: Unspecified routes are routes where the port of load/unload was not provided by the data suppliers.
A6: Note 2 | B6: For container figures after 2004 are not directly comparable with earlier years. Please see the section "Port freight statistics: unitised traffic category changes from 2000" of the Notes and Definitions for details (link below to the technical notes). This does not affect other cargo categories or totals.
A7: Note 3 | B7: Bulk fuels include liquified gas, crude oil, oil products and coal. Other bulks includes other liquid bulk products, ores, agricultural products and other dry bulk.
A8: Note 4 | B8: Ports were affected by measures to prevent and reduce the global spread of Covid-19 throughout 2020, as well as the EU transition period. The extent of the impact of either are not quantified in this data series, however comparative analysis and commentary are included in the release.
A9: Note 5 | B9: Data for roll-on/roll-off traffic for Hull in 2019 has been revised.
A10: Note 6 | B10: Data for container (lo-lo) and roll-on/roll-off traffic for London from 2019 to 2023 has been revised.
A11: Note 7 | B11: In 2025, freight traffic data on two new cargo type breakdowns were collected from major UK ports: wood pellets (previously categorised as ‘other dry bulk’) and wind farm products (previously categorised as ‘other general cargo’). Totals for ‘other dry bulk’ and ‘other general cargo’ will appear lower in 2025 due to this cargo recategorisation.

Sheet Data
A1: Data sheet for PORT0201
A2: This worksheet contains 1 table.
A3: This sheet includes the data presented in PORT0201.
A4: Year | B4: CargoCode | C4: Direction | D4: Tonnage | E4: Units | F4: Region | G4: TEU | H4: Dummy
A5: 2000 | B5: 11 | C5: Both Directions | D5: 2374.6875 | E5: 0 | F5: Domestic | H5: 1
A6: 2000 | B6: 11 | C6: Both Directions | D6: 4115.3066 | E6: 0 | F6: International | H6: 1
A7: 2000 | B7: 11 | C7: Both Directions | D7: 9.740905 | E7: 0 | F7: Unspecified | H7: 1
A8: 2000 | B8: 11 | C8: Inwards | D8: 1185.7779 | E8: 0 | F8: Domestic | H8: 1
A9: 2000 | B9: 11 | C9: Inwards | D9: 580.06664 | E9: 0 | F9: International | H9: 1
A10: 2000 | B10: 11 | C10: Inwards | D10: 1.0524405 | E10: 0 | F10: Unspecified | H10: 1
A11: 2000 | B11: 11 | C11: Outwards | D11: 3535.2399 | E11: 0 | F11: International | H11: 1
A12: 2000 | B12: 11 | C12: Outwards | D12: 8.6884645 | E12: 0 | F12: Unspecified | H12: 1
A13: 2000 | B13: 11 | C13: Outwards | D13: 1188.9096 | E13: 0 | F13: Domestic | H13: 1
A14: 2000 | B14: 12 | C14: Both Directions | D14: 101.146 | E14: 0 | F14: Unspecified | H14: 1
A15: 2000 | B15: 12 | C15: Both Directions | D15: 61409.377 | E15: 0 | F15: Domestic | H15: 1
A16: 2000 | B16: 12 | C16: Both Directions | D16: 122833.83 | E16: 0 | F16: International | H16: 1
... A75: 2000 | B75: 29 | C75: Outwards | D75: 3.9960758 | E75: 0 | F75: Unspecified | H75: 1
A76: 2000 | B76: 31 | C76: Both Directions | D76: 75.41766 | E76: 42.386476 | F76: Unspecified | G76: 42.386478 | H76: 1
A77: 2000 | B77: 31 | C77: Both Directions | D77: 870.28506 | E77: 91.652042 | F77: Domestic | G77: 91.652045 | H77: 1
A78: 2000 | B78: 31 | C78: Both Directions | D78: 22096.675 | E78: 1766.9685 | F78: International | G78: 1766.9685 | H78: 1
A79: 2000 | B79: 31 | C79: Inwards | D79: 490.84769 | E79: 45.936767 | F79: Domestic | G79: 45.936777 | H79: 1
A80: 2000 | B80: 31 | C80: Inwards | D80: 12037.105 | E80: 911.44949 | F80: International | G80: 911.44956 | H80: 1
A81: 2000 | B81: 31 | C81: Inwards | D81: 15.479346 | E81: 4.4157413 | F81: Unspecified | G81: 4.4157416 | H81: 1
A82: 2000 | B82: 31 | C82: Outwards | D82: 59.938314 | E82: 37.970735 | F82: Unspecified | G82: 37.970736 | H82: 1
A83: 2000 | B83: 31 | C83: Outwards | D83: 10059.57 | E83: 855.51899 | F83: International | G83: 855.51895 | H83: 1
A84: 2000 | B84: 31 | C84: Outwards | D84: 379.43738 | E84: 45.715275 | F84: Domestic | G84: 45.715268 | H84: 1
A85: 2000 | B85: 32 | C85: Both Directions | D85: 1184.0292 | E85: 121.58501 | F85: Domestic | G85: 243.16996 | H85: 1
A86: 2000 | B86: 32 | C86: Both Directions | D86: 25273.468 | E86: 2064.882 | F86: International | G86: 4129.7637 | H86: 1
A87: 2000 | B87: 32 | C87: Both Directions | D87: 13.586742 | E87: 64.393039 | F87: Unspecified | G87: 128.7861 | H87: 1
... A110: 2000 | B110: 34 | C110: Outwards | D110: 2.4877971 | E110: 0.90979846 | F110: Domestic | G110: 2.047047 | H110: 1
A111: 2000 | B111: 51 | C111: Both Directions | D111: 7172.8837 | E111: 606.76382 | F111: Domestic | H111: 1
A112: 2000 | B112: 51 | C112: Both Directions | D112: 28043.723 | E112: 2439.4892 | F112: International | H112: 1
A113: 2000 | B113: 51 | C113: Both Directions | D113: 28.46 | E113: 19.132 | F113: Unspecified | H113: 1
A114: 2000 | B114: 51 | C114: Inwards | D114: 28.386 | E114: 19.125 | F114: Unspecified | H114: 1
A115: 2000 | B115: 51 | C115: Inwards | D115: 3729.5081 | E115: 302.50479 | F115: Domestic | H115: 1
A116: 2000 | B116: 51 | C116: Inwards | D116: 15875.638 | E116: 1210.4332 | F116: International | H116: 1
A117: 2000 | B117: 51 | C117: Outwards | D117: 0.074 | E117: 0.007 | F117: Unspecified | H117: 1
A118: 2000 | B118: 51 | C118: Outwards | D118: 3443.3756 | E118: 304.25903 | F118: Domestic | H118: 1
A119: 2000 | B119: 51 | C119: Outwards | D119: 12168.085 | E119: 1229.056 | F119: International | H119: 1
A120: 2000 | B120: 52 | C120: Both Directions | D120: 0 | E120: 0.001 | F120: Unspecified | H120: 1
...

Sheet Working
A1: Working Version PORT0201: UK major port freight traffic by cargo type and year (filter by direction and route) from 2000
A2: NOTE: Colours refer to cells that have identical formulae | G2: =port0201!$B$8 -> Tonnage | H2: =CONCATENATE("Thousand ",CHOOSE(VLOOKUP(port0201!$B$8,Lookup!$A$1:$B$3,2,FALSE),"tonnes","units","TEUs")) -> Thousand tonnes | AD2: Totals Check
C3: Route | D3: =port0201!$B$9 -> All Routes | E3: =port0201!$B$9 -> All Routes | F3: =port0201!$B$9 -> All Routes | G3: =port0201!$B$9 -> All Routes | H3: =port0201!$B$9 -> All Routes | I3: =port0201!$B$9 -> All Routes | J3: =port0201!$B$9 -> All Routes | K3: =port0201!$B$9 -> All Routes | ... AC3: =port0201!$B$9 -> All Routes
C4: Direction | D4: =port0201!$B$7 -> Both Directions | E4: =port0201!$B$7 -> Both Directions | F4: =port0201!$B$7 -> Both Directions | G4: =port0201!$B$7 -> Both Directions | H4: =port0201!$B$7 -> Both Directions | I4: =port0201!$B$7 -> Both Directions | J4: =port0201!$B$7 -> Both Directions | K4: =port0201!$B$7 -> Both Directions | ... AC4: =port0201!$B$7 -> Both Directions
A5: Cargo Group | B5: Cargo Categories, [Groups] | C5: Year | D5: 2000 | E5: 2001 | F5: 2002 | G5: 2003 | H5: 2004 | I5: 2005 | J5: 2006 | K5: 2007 | L5: 2008 | M5: 2009 | N5: 2010 | O5: 2011 | P5: 2012 | Q5: 2013 | R5: 2014 | S5: 2015 | T5: 2016 | U5: 2017 | V5: 2018 | W5: 2019 | X5: 2020 | Y5: 2021 | Z5: 2022 | AA5: 2023 | AB5: 2024 | AC5: 2025 | AE5: % change | AF5: absolute change | AK5: % Difference
A6: Liquid bulk | B6: 11 | C6: Liquefied gas | D6: =IF(port0201!$B$9="All Routes",IF(port0201!$B$8<>"Tonnage","z",ROUND(SUMIFS(Data!$D:$D,Data!$A:$A,D$5,Data!$C:$C,D$4,Data!$B:$B,$B6),3)),IF(port0201!$B$8<>"Tonnage","z",ROUND(SUMIFS(Data!$D:$D,Data!$A:$A,D$5,Data!$C:$C,D$4,Data!$B:$B,$B6,Data!$F:$F,port0201!$B$9),3))) -> 6499.735 | E6: =IF(port0201!$B$9="All Routes",IF(port0201!$B$8<>"Tonnage","z",ROUND(SUMIFS(Data!$D:$D,Data!$A:$A,E$5,Data!$C:$C,E$4,Data!$B:$B,$B6),3)),IF(port0201!$B$8<>"Tonnage","z",ROUND(SUMIFS(Data!$D:$D,Data!$A:$A,E$5,Data!$C:$C,E$4,Data!$B:$B,$B6,Data!$F:$F,port0201!$B$9),3))) -> 8051.473 | F6: =IF(port0201!$B$9="All Routes",IF(port0201!$B$8<>"Tonnage","z",ROUND(SUMIFS(Data!$D:$D,Data!$A:$A,F$5,Data!$C:$C,F$4,Data!$B:$B,$B6),3)),IF(port0201!$B$8<>"Tonnage","z",ROUND(SUMIFS(Data!$D:$D,Data!$A:$A,F$5,Data!$C:$C,F$4,Data!$B:$B,$B6,Data!$F:$F,port0201!$B$9),3))) -> 7850.18 | G6: =IF(port0201!$B$9="All Routes",IF(port0201!$B$8<>"Tonnage","z",ROUND(SUMIFS(Data!$D:$D,Data!$A:$A,G$5,Data!$C:$C,G$4,Data!$B:$B,$B6),3)),IF(port0201!$B$8<>"Tonnage","z",ROUND(SUMIFS(Data!$D:$D,Data!$A:$A,G$5,Data!$C:$C,G$4,Data!$B:$B,$B6,Data!$F:$F,port0201!$B$9),3))) -> 7542.956 | H6: =IF(port0201!$B$9="All Routes",IF(port0201!$B$8<>"Tonnage","z",ROUND(SUMIFS(Data!$D:$D,Data!$A:$A,H$5,Data!$C:$C,H$4,Data!$B:$B,$B6),3)),IF(port0201!$B$8<>"Tonnage","z",ROUND(SUMIFS(Data!$D:$D,Data!$A:$A,H$5,Data!$C:$C,H$4,Data!$B:$B,$B6,Data!$F:$F,port0201!$B$9),3))) -> 7410.348 | I6: =IF(port0201!$B$9="All Routes",IF(port0201!$B$8<>"Tonnage","z",ROUND(SUMIFS(Data!$D:$D,Data!$A:$A,I$5,Data!$C:$C,I$4,Data!$B:$B,$B6),3)),IF(port0201!$B$8<>"Tonnage","z",ROUND(SUMIFS(Data!$D:$D,Data!$A:$A,I$5,Data!$C:$C,I$4,Data!$B:$B,$B6,Data!$F:$F,port0201!$B$9),3))) -> 7899.554 | J6: =IF(port0201!$B$9="All Routes",IF(port0201!$B$8<>"Tonnage","z",ROUND(SUMIFS(Data!$D:$D,Data!$A:$A,J$5,Data!$C:$C,J$4,Data!$B:$B,$B6),3)),IF(port0201!$B$8<>"Tonnage","z",ROUND(SUMIFS(Data!$D:$D,Data!$A:$A,J$5,Data!$C:$C,J$4,Data!$B:$B,$B6,Data!$F:$F,port0201!$B$9),3))) -> 9470.601 | K6: =IF(port0201!$B$9="All Routes",IF(port0201!$B$8<>"Tonnage","z",ROUND(SUMIFS(Data!$D:$D,Data!$A:$A,K$5,Data!$C:$C,K$4,Data!$B:$B,$B6),3)),IF(port0201!$B$8<>"Tonnage","z",ROUND(SUMIFS(Data!$D:$D,Data!$A:$A,K$5,Data!$C:$C,K$4,Data!$B:$B,$B6,Data!$F:$F,port0201!$B$9),3))) -> 7901.754 | ... AC6: =IF(port0201!$B$9="All Routes",IF(port0201!$B$8<>"Tonnage","z",ROUND(SUMIFS(Data!$D:$D,Data!$A:$A,AC$5,Data!$C:$C,AC$4,Data!$B:$B,$B6),3)),IF(port0201!$B$8<>"Tonnage","z",ROUND(SUMIFS(Data!$D:$D,Data!$A:$A,AC$5,Data!$C:$C,AC$4,Data!$B:$B,$B6,Data!$F:$F,port0201!$B$9),3))) -> 16954.295 | AE6: =(AC6-AB6)/AB6 -> 0.21933265 | AF6: =AC6-AB6 -> 3049.726 | AH6: 111155 | AJ6: =AB6-AA6 -> -4050.383 | AK6: =AJ6/AA6 -> -0.22558584
A7: Liquid bulk | B7: 12 | C7: Crude oil | D7: =IF(port0201!$B$9="All Routes",IF(port0201!$B$8<>"Tonnage","z",ROUND(SUMIFS(Data!$D:$D,Data!$A:$A,D$5,Data!$C:$C,D$4,Data!$B:$B,$B7),3)),IF(port0201!$B$8<>"Tonnage","z",ROUND(SUMIFS(Data!$D:$D,Data!$A:$A,D$5,Data!$C:$C,D$4,Data!$B:$B,$B7,Data!$F:$F,port0201!$B$9),3))) -> 184344.35 | E7: =IF(port0201!$B$9="All Routes",IF(port0201!$B$8<>"Tonnage","z",ROUND(SUMIFS(Data!$D:$D,Data!$A:$A,E$5,Data!$C:$C,E$4,Data!$B:$B,$B7),3)),IF(port0201!$B$8<>"Tonnage","z",ROUND(SUMIFS(Data!$D:$D,Data!$A:$A,E$5,Data!$C:$C,E$4,Data!$B:$B,$B7,Data!$F:$F,port0201!$B$9),3))) -> 168557.06 | F7: =IF(port0201!$B$9="All Routes",IF(port0201!$B$8<>"Tonnage","z",ROUND(SUMIFS(Data!$D:$D,Data!$A:$A,F$5,Data!$C:$C,F$4,Data!$B:$B,$B7),3)),IF(port0201!$B$8<>"Tonnage","z",ROUND(SUMIFS(Data!$D:$D,Data!$A:$A,F$5,Data!$C:$C,F$4,Data!$B:$B,$B7,Data!$F:$F,port0201!$B$9),3))) -> 172523.73 | G7: =IF(port0201!$B$9="All Routes",IF(port0201!$B$8<>"Tonnage","z",ROUND(SUMIFS(Data!$D:$D,Data!$A:$A,G$5,Data!$C:$C,G$4,Data!$B:$B,$B7),3)),IF(port0201!$B$8<>"Tonnage","z",ROUND(SUMIFS(Data!$D:$D,Data!$A:$A,G$5,Data!$C:$C,G$4,Data!$B:$B,$B7,Data!$F:$F,port0201!$B$9),3))) -> 160318.89 | H7: =IF(port0201!$B$9="All Routes",IF(port0201!$B$8<>"Tonnage","z",ROUND(SUMIFS(Data!$D:$D,Data!$A:$A,H$5,Data!$C:$C,H$4,Data!$B:$B,$B7),3)),IF(port0201!$B$8<>"Tonnage","z",ROUND(SUMIFS(Data!$D:$D,Data!$A:$A,H$5,Data!$C:$C,H$4,Data!$B:$B,$B7,Data!$F:$F,port0201!$B$9),3))) -> 161595.49 | I7: =IF(port0201!$B$9="All Routes",IF(port0201!$B$8<>"Tonnage","z",ROUND(SUMIFS(Data!$D:$D,Data!$A:$A,I$5,Data!$C:$C,I$4,Data!$B:$B,$B7),3)),IF(port0201!$B$8<>"Tonnage","z",ROUND(SUMIFS(Data!$D:$D,Data!$A:$A,I$5,Data!$C:$C,I$4,Data!$B:$B,$B7,Data!$F:$F,port0201!$B$9),3))) -> 153498.95 | J7: =IF(port0201!$B$9="All Routes",IF(port0201!$B$8<>"Tonnage","z",ROUND(SUMIFS(Data!$D:$D,Data!$A:$A,J$5,Data!$C:$C,J$4,Data!$B:$B,$B7),3)),IF(port0201!$B$8<>"Tonnage","z",ROUND(SUMIFS(Data!$D:$D,Data!$A:$A,J$5,Data!$C:$C,J$4,Data!$B:$B,$B7,Data!$F:$F,port0201!$B$9),3))) -> 142200.27 | K7: =IF(port0201!$B$9="All Routes",IF(port0201!$B$8<>"Tonnage","z",ROUND(SUMIFS(Data!$D:$D,Data!$A:$A,K$5,Data!$C:$C,K$4,Data!$B:$B,$B7),3)),IF(port0201!$B$8<>"Tonnage","z",ROUND(SUMIFS(Data!$D:$D,Data!$A:$A,K$5,Data!$C:$C,K$4,Data!$B:$B,$B7,Data!$F:$F,port0201!$B$9),3))) -> 140131.86 | ... AC7: =IF(port0201!$B$9="All Routes",IF(port0201!$B$8<>"Tonnage","z",ROUND(SUMIFS(Data!$D:$D,Data!$A:$A,AC$5,Data!$C:$C,AC$4,Data!$B:$B,$B7),3)),IF(port0201!$B$8<>"Tonnage","z",ROUND(SUMIFS(Data!$D:$D,Data!$A:$A,AC$5,Data!$C:$C,AC$4,Data!$B:$B,$B7,Data!$F:$F,port0201!$B$9),3))) -> 62509.23 | AE7: =(AC7-AB7)/AB7 -> -0.11073644 | AF7: =AC7-AB7 -> -7784.025 | AH7: 137364 | AJ7: =AB7-AA7 -> -3390.832 | AK7: =AJ7/AA7 -> -0.046018511
A8: Liquid bulk | B8: 13 | C8: Oil products | D8: =IF(port0201!$B$9="All Routes",IF(port0201!$B$8<>"Tonnage","z",ROUND(SUMIFS(Data!$D:$D,Data!$A:$A,D$5,Data!$C:$C,D$4,Data!$B:$B,$B8),3)),IF(port0201!$B$8<>"Tonnage","z",ROUND(SUMIFS(Data!$D:$D,Data!$A:$A,D$5,Data!$C:$C,D$4,Data!$B:$B,$B8,Data!$F:$F,port0201!$B$9),3))) -> 86249.525 | E8: =IF(port0201!$B$9="All Routes",IF(port0201!$B$8<>"Tonnage","z",ROUND(SUMIFS(Data!$D:$D,Data!$A:$A,E$5,Data!$C:$C,E$4,Data!$B:$B,$B8),3)),IF(port0201!$B$8<>"Tonnage","z",ROUND(SUMIFS(Data!$D:$D,Data!$A:$A,E$5,Data!$C:$C,E$4,Data!$B:$B,$B8,Data!$F:$F,port0201!$B$9),3))) -> 82592.958 | F8: =IF(port0201!$B$9="All Routes",IF(port0201!$B$8<>"Tonnage","z",ROUND(SUMIFS(Data!$D:$D,Data!$A:$A,F$5,Data!$C:$C,F$4,Data!$B:$B,$B8),3)),IF(port0201!$B$8<>"Tonnage","z",ROUND(SUMIFS(Data!$D:$D,Data!$A:$A,F$5,Data!$C:$C,F$4,Data!$B:$B,$B8,Data!$F:$F,port0201!$B$9),3))) -> 78163.916 | G8: =IF(port0201!$B$9="All Routes",IF(port0201!$B$8<>"Tonnage","z",ROUND(SUMIFS(Data!$D:$D,Data!$A:$A,G$5,Data!$C:$C,G$4,Data!$B:$B,$B8),3)),IF(port0201!$B$8<>"Tonnage","z",ROUND(SUMIFS(Data!$D:$D,Data!$A:$A,G$5,Data!$C:$C,G$4,Data!$B:$B,$B8,Data!$F:$F,port0201!$B$9),3))) -> 80351.013 | H8: =IF(port0201!$B$9="All Routes",IF(port0201!$B$8<>"Tonnage","z",ROUND(SUMIFS(Data!$D:$D,Data!$A:$A,H$5,Data!$C:$C,H$4,Data!$B:$B,$B8),3)),IF(port0201!$B$8<>"Tonnage","z",ROUND(SUMIFS(Data!$D:$D,Data!$A:$A,H$5,Data!$C:$C,H$4,Data!$B:$B,$B8,Data!$F:$F,port0201!$B$9),3))) -> 85975.959 | I8: =IF(port0201!$B$9="All Routes",IF(port0201!$B$8<>"Tonnage","z",ROUND(SUMIFS(Data!$D:$D,Data!$A:$A,I$5,Data!$C:$C,I$4,Data!$B:$B,$B8),3)),IF(port0201!$B$8<>"Tonnage","z",ROUND(SUMIFS(Data!$D:$D,Data!$A:$A,I$5,Data!$C:$C,I$4,Data!$B:$B,$B8,Data!$F:$F,port0201!$B$9),3))) -> 89000.682 | J8: =IF(port0201!$B$9="All Routes",IF(port0201!$B$8<>"Tonnage","z",ROUND(SUMIFS(Data!$D:$D,Data!$A:$A,J$5,Data!$C:$C,J$4,Data!$B:$B,$B8),3)),IF(port0201!$B$8<>"Tonnage","z",ROUND(SUMIFS(Data!$D:$D,Data!$A:$A,J$5,Data!$C:$C,J$4,Data!$B:$B,$B8,Data!$F:$F,port0201!$B$9),3))) -> 85119.501 | K8: =IF(port0201!$B$9="All Routes",IF(port0201!$B$8<>"Tonnage","z",ROUND(SUMIFS(Data!$D:$D,Data!$A:$A,K$5,Data!$C:$C,K$4,Data!$B:$B,$B8),3)),IF(port0201!$B$8<>"Tonnage","z",ROUND(SUMIFS(Data!$D:$D,Data!$A:$A,K$5,Data!$C:$C,K$4,Data!$B:$B,$B8,Data!$F:$F,port0201!$B$9),3))) -> 85960.272 | ... AC8: =IF(port0201!$B$9="All Routes",IF(port0201!$B$8<>"Tonnage","z",ROUND(SUMIFS(Data!$D:$D,Data!$A:$A,AC$5,Data!$C:$C,AC$4,Data!$B:$B,$B8),3)),IF(port0201!$B$8<>"Tonnage","z",ROUND(SUMIFS(Data!$D:$D,Data!$A:$A,AC$5,Data!$C:$C,AC$4,Data!$B:$B,$B8,Data!$F:$F,port0201!$B$9),3))) -> 72004.882 | AE8: =(AC8-AB8)/AB8 -> 0.022271674 | AF8: =AC8-AB8 -> 1568.731 | AJ8: =AB8-AA8 -> 1335.593 | AK8: =AJ8/AA8 -> 0.019328252
A9: Liquid bulk | B9: 19 | C9: Other liquid bulk products | D9: =IF(port0201!$B$9="All Routes",IF(port0201!$B$8<>"Tonnage","z",ROUND(SUMIFS(Data!$D:$D,Data!$A:$A,D$5,Data!$C:$C,D$4,Data!$B:$B,$B9),3)),IF(port0201!$B$8<>"Tonnage","z",ROUND(SUMIFS(Data!$D:$D,Data!$A:$A,D$5,Data!$C:$C,D$4,Data!$B:$B,$B9,Data!$F:$F,port0201!$B$9),3))) -> 13456.65 | E9: =IF(port0201!$B$9="All Routes",IF(port0201!$B$8<>"Tonnage","z",ROUND(SUMIFS(Data!$D:$D,Data!$A:$A,E$5,Data!$C:$C,E$4,Data!$B:$B,$B9),3)),IF(port0201!$B$8<>"Tonnage","z",ROUND(SUMIFS(Data!$D:$D,Data!$A:$A,E$5,Data!$C:$C,E$4,Data!$B:$B,$B9,Data!$F:$F,port0201!$B$9),3))) -> 14332.779 | F9: =IF(port0201!$B$9="All Routes",IF(port0201!$B$8<>"Tonnage","z",ROUND(SUMIFS(Data!$D:$D,Data!$A:$A,F$5,Data!$C:$C,F$4,Data!$B:$B,$B9),3)),IF(port0201!$B$8<>"Tonnage","z",ROUND(SUMIFS(Data!$D:$D,Data!$A:$A,F$5,Data!$C:$C,F$4,Data!$B:$B,$B9,Data!$F:$F,port0201!$B$9),3))) -> 12257.988 | G9: =IF(port0201!$B$9="All Routes",IF(port0201!$B$8<>"Tonnage","z",ROUND(SUMIFS(Data!$D:$D,Data!$A:$A,G$5,Data!$C:$C,G$4,Data!$B:$B,$B9),3)),IF(port0201!$B$8<>"Tonnage","z",ROUND(SUMIFS(Data!$D:$D,Data!$A:$A,G$5,Data!$C:$C,G$4,Data!$B:$B,$B9,Data!$F:$F,port0201!$B$9),3))) -> 12086.552 | H9: =IF(port0201!$B$9="All Routes",IF(port0201!$B$8<>"Tonnage","z",ROUND(SUMIFS(Data!$D:$D,Data!$A:$A,H$5,Data!$C:$C,H$4,Data!$B:$B,$B9),3)),IF(port0201!$B$8<>"Tonnage","z",ROUND(SUMIFS(Data!$D:$D,Data!$A:$A,H$5,Data!$C:$C,H$4,Data!$B:$B,$B9,Data!$F:$F,port0201!$B$9),3))) -> 12451.715 | I9: =IF(port0201!$B$9="All Routes",IF(port0201!$B$8<>"Tonnage","z",ROUND(SUMIFS(Data!$D:$D,Data!$A:$A,I$5,Data!$C:$C,I$4,Data!$B:$B,$B9),3)),IF(port0201!$B$8<>"Tonnage","z",ROUND(SUMIFS(Data!$D:$D,Data!$A:$A,I$5,Data!$C:$C,I$4,Data!$B:$B,$B9,Data!$F:$F,port0201!$B$9),3))) -> 12767.421 | J9: =IF(port0201!$B$9="All Routes",IF(port0201!$B$8<>"Tonnage","z",ROUND(SUMIFS(Data!$D:$D,Data!$A:$A,J$5,Data!$C:$C,J$4,Data!$B:$B,$B9),3)),IF(port0201!$B$8<>"Tonnage","z",ROUND(SUMIFS(Data!$D:$D,Data!$A:$A,J$5,Data!$C:$C,J$4,Data!$B:$B,$B9,Data!$F:$F,port0201!$B$9),3))) -> 13597.769 | K9: =IF(port0201!$B$9="All Routes",IF(port0201!$B$8<>"Tonnage","z",ROUND(SUMIFS(Data!$D:$D,Data!$A:$A,K$5,Data!$C:$C,K$4,Data!$B:$B,$B9),3)),IF(port0201!$B$8<>"Tonnage","z",ROUND(SUMIFS(Data!$D:$D,Data!$A:$A,K$5,Data!$C:$C,K$4,Data!$B:$B,$B9,Data!$F:$F,port0201!$B$9),3))) -> 14598.533 | ... AC9: =IF(port0201!$B$9="All Routes",IF(port0201!$B$8<>"Tonnage","z",ROUND(SUMIFS(Data!$D:$D,Data!$A:$A,AC$5,Data!$C:$C,AC$4,Data!$B:$B,$B9),3)),IF(port0201!$B$8<>"Tonnage","z",ROUND(SUMIFS(Data!$D:$D,Data!$A:$A,AC$5,Data!$C:$C,AC$4,Data!$B:$B,$B9,Data!$F:$F,port0201!$B$9),3))) -> 8519.245 | AE9: =(AC9-AB9)/AB9 -> 0.0063239838 | AF9: =AC9-AB9 -> 53.537 | AJ9: =AB9-AA9 -> -59.46 | AK9: =AJ9/AA9 -> -0.0069746426
A10: Liquid bulk | B10: All Liquid Bulk | C10: All Routes liquid bulk traffic | D10: =IF(port0201!$B$8<>"Tonnage","z",ROUND(SUM(D6:D9),3)) -> 290550.26 | E10: =IF(port0201!$B$8<>"Tonnage","z",ROUND(SUM(E6:E9),3)) -> 273534.27 | F10: =IF(port0201!$B$8<>"Tonnage","z",ROUND(SUM(F6:F9),3)) -> 270795.81 | G10: =IF(port0201!$B$8<>"Tonnage","z",ROUND(SUM(G6:G9),3)) -> 260299.41 | H10: =IF(port0201!$B$8<>"Tonnage","z",ROUND(SUM(H6:H9),3)) -> 267433.51 | I10: =IF(port0201!$B$8<>"Tonnage","z",ROUND(SUM(I6:I9),3)) -> 263166.6 | J10: =IF(port0201!$B$8<>"Tonnage","z",ROUND(SUM(J6:J9),3)) -> 250388.14 | K10: =IF(port0201!$B$8<>"Tonnage","z",ROUND(SUM(K6:K9),3)) -> 248592.42 | ... AC10: =IF(port0201!$B$8<>"Tonnage","z",ROUND(SUM(AC6:AC9),3)) -> 159987.65 | AD10: =SUM(AB6:AB9)-AB10 -> 0 | AE10: =(AC10-AB10)/AB10 -> -0.019080546 | AF10: =AC10-AB10 -> -3112.031 | AG10: =AC10/AC36 -> 0.38134134 | AH10: =(AH7-AH6)/AH6 -> 0.23578786 | AJ10: =AB10-AA10 -> -6165.082 | AK10: =AJ10/AA10 -> -0.036422713
A11: Dry bulk | B11: 21 | C11: Ores | D11: =IF(port0201!$B$9="All Routes",IF(port0201!$B$8<>"Tonnage","z",ROUND(SUMIFS(Data!$D:$D,Data!$A:$A,D$5,Data!$C:$C,D$4,Data!$B:$B,$B11),3)),IF(port0201!$B$8<>"Tonnage","z",ROUND(SUMIFS(Data!$D:$D,Data!$A:$A,D$5,Data!$C:$C,D$4,Data!$B:$B,$B11,Data!$F:$F,port0201!$B$9),3))) -> 20318.624 | E11: =IF(port0201!$B$9="All Routes",IF(port0201!$B$8<>"Tonnage","z",ROUND(SUMIFS(Data!$D:$D,Data!$A:$A,E$5,Data!$C:$C,E$4,Data!$B:$B,$B11),3)),IF(port0201!$B$8<>"Tonnage","z",ROUND(SUMIFS(Data!$D:$D,Data!$A:$A,E$5,Data!$C:$C,E$4,Data!$B:$B,$B11,Data!$F:$F,port0201!$B$9),3))) -> 19559.76 | F11: =IF(port0201!$B$9="All Routes",IF(port0201!$B$8<>"Tonnage","z",ROUND(SUMIFS(Data!$D:$D,Data!$A:$A,F$5,Data!$C:$C,F$4,Data!$B:$B,$B11),3)),IF(port0201!$B$8<>"Tonnage","z",ROUND(SUMIFS(Data!$D:$D,Data!$A:$A,F$5,Data!$C:$C,F$4,Data!$B:$B,$B11,Data!$F:$F,port0201!$B$9),3))) -> 17009.198 | G11: =IF(port0201!$B$9="All Routes",IF(port0201!$B$8<>"Tonnage","z",ROUND(SUMIFS(Data!$D:$D,Data!$A:$A,G$5,Data!$C:$C,G$4,Data!$B:$B,$B11),3)),IF(port0201!$B$8<>"Tonnage","z",ROUND(SUMIFS(Data!$D:$D,Data!$A:$A,G$5,Data!$C:$C,G$4,Data!$B:$B,$B11,Data!$F:$F,port0201!$B$9),3))) -> 17988.786 | H11: =IF(port0201!$B$9="All Routes",IF(port0201!$B$8<>"Tonnage","z",ROUND(SUMIFS(Data!$D:$D,Data!$A:$A,H$5,Data!$C:$C,H$4,Data!$B:$B,$B11),3)),IF(port0201!$B$8<>"Tonnage","z",ROUND(SUMIFS(Data!$D:$D,Data!$A:$A,H$5,Data!$C:$C,H$4,Data!$B:$B,$B11,Data!$F:$F,port0201!$B$9),3))) -> 17826.584 | I11: =IF(port0201!$B$9="All Routes",IF(port0201!$B$8<>"Tonnage","z",ROUND(SUMIFS(Data!$D:$D,Data!$A:$A,I$5,Data!$C:$C,I$4,Data!$B:$B,$B11),3)),IF(port0201!$B$8<>"Tonnage","z",ROUND(SUMIFS(Data!$D:$D,Data!$A:$A,I$5,Data!$C:$C,I$4,Data!$B:$B,$B11,Data!$F:$F,port0201!$B$9),3))) -> 17940.509 | J11: =IF(port0201!$B$9="All Routes",IF(port0201!$B$8<>"Tonnage","z",ROUND(SUMIFS(Data!$D:$D,Data!$A:$A,J$5,Data!$C:$C,J$4,Data!$B:$B,$B11),3)),IF(port0201!$B$8<>"Tonnage","z",ROUND(SUMIFS(Data!$D:$D,Data!$A:$A,J$5,Data!$C:$C,J$4,Data!$B:$B,$B11,Data!$F:$F,port0201!$B$9),3))) -> 18300.511 | K11: =IF(port0201!$B$9="All Routes",IF(port0201!$B$8<>"Tonnage","z",ROUND(SUMIFS(Data!$D:$D,Data!$A:$A,K$5,Data!$C:$C,K$4,Data!$B:$B,$B11),3)),IF(port0201!$B$8<>"Tonnage","z",ROUND(SUMIFS(Data!$D:$D,Data!$A:$A,K$5,Data!$C:$C,K$4,Data!$B:$B,$B11,Data!$F:$F,port0201!$B$9),3))) -> 19144.281 | ... AC11: =IF(port0201!$B$9="All Routes",IF(port0201!$B$8<>"Tonnage","z",ROUND(SUMIFS(Data!$D:$D,Data!$A:$A,AC$5,Data!$C:$C,AC$4,Data!$B:$B,$B11),3)),IF(port0201!$B$8<>"Tonnage","z",ROUND(SUMIFS(Data!$D:$D,Data!$A:$A,AC$5,Data!$C:$C,AC$4,Data!$B:$B,$B11,Data!$F:$F,port0201!$B$9),3))) -> 9963.657 | AE11: =(AC11-AB11)/AB11 -> -0.12659719 | AF11: =AC11-AB11 -> -1444.203 | AG11: =AC11-AB11 -> -1444.203 | AJ11: =AB11-AA11 -> -1857.581 | AK11: =AJ11/AA11 -> -0.14003161
A12: Dry bulk | B12: 22 | C12: Coal | D12: =IF(port0201!$B$9="All Routes",IF(port0201!$B$8<>"Tonnage","z",ROUND(SUMIFS(Data!$D:$D,Data!$A:$A,D$5,Data!$C:$C,D$4,Data!$B:$B,$B12),3)),IF(port0201!$B$8<>"Tonnage","z",ROUND(SUMIFS(Data!$D:$D,Data!$A:$A,D$5,Data!$C:$C,D$4,Data!$B:$B,$B12,Data!$F:$F,port0201!$B$9),3))) -> 27830.277 | E12: =IF(port0201!$B$9="All Routes",IF(port0201!$B$8<>"Tonnage","z",ROUND(SUMIFS(Data!$D:$D,Data!$A:$A,E$5,Data!$C:$C,E$4,Data!$B:$B,$B12),3)),IF(port0201!$B$8<>"Tonnage","z",ROUND(SUMIFS(Data!$D:$D,Data!$A:$A,E$5,Data!$C:$C,E$4,Data!$B:$B,$B12,Data!$F:$F,port0201!$B$9),3))) -> 39919.835 | F12: =IF(port0201!$B$9="All Routes",IF(port0201!$B$8<>"Tonnage","z",ROUND(SUMIFS(Data!$D:$D,Data!$A:$A,F$5,Data!$C:$C,F$4,Data!$B:$B,$B12),3)),IF(port0201!$B$8<>"Tonnage","z",ROUND(SUMIFS(Data!$D:$D,Data!$A:$A,F$5,Data!$C:$C,F$4,Data!$B:$B,$B12,Data!$F:$F,port0201!$B$9),3))) -> 32998.074 | G12: =IF(port0201!$B$9="All Routes",IF(port0201!$B$8<>"Tonnage","z",ROUND(SUMIFS(Data!$D:$D,Data!$A:$A,G$5,Data!$C:$C,G$4,Data!$B:$B,$B12),3)),IF(port0201!$B$8<>"Tonnage","z",ROUND(SUMIFS(Data!$D:$D,Data!$A:$A,G$5,Data!$C:$C,G$4,Data!$B:$B,$B12,Data!$F:$F,port0201!$B$9),3))) -> 37280.728 | H12: =IF(port0201!$B$9="All Routes",IF(port0201!$B$8<>"Tonnage","z",ROUND(SUMIFS(Data!$D:$D,Data!$A:$A,H$5,Data!$C:$C,H$4,Data!$B:$B,$B12),3)),IF(port0201!$B$8<>"Tonnage","z",ROUND(SUMIFS(Data!$D:$D,Data!$A:$A,H$5,Data!$C:$C,H$4,Data!$B:$B,$B12,Data!$F:$F,port0201!$B$9),3))) -> 41315.997 | I12: =IF(port0201!$B$9="All Routes",IF(port0201!$B$8<>"Tonnage","z",ROUND(SUMIFS(Data!$D:$D,Data!$A:$A,I$5,Data!$C:$C,I$4,Data!$B:$B,$B12),3)),IF(port0201!$B$8<>"Tonnage","z",ROUND(SUMIFS(Data!$D:$D,Data!$A:$A,I$5,Data!$C:$C,I$4,Data!$B:$B,$B12,Data!$F:$F,port0201!$B$9),3))) -> 51787.366 | J12: =IF(port0201!$B$9="All Routes",IF(port0201!$B$8<>"Tonnage","z",ROUND(SUMIFS(Data!$D:$D,Data!$A:$A,J$5,Data!$C:$C,J$4,Data!$B:$B,$B12),3)),IF(port0201!$B$8<>"Tonnage","z",ROUND(SUMIFS(Data!$D:$D,Data!$A:$A,J$5,Data!$C:$C,J$4,Data!$B:$B,$B12,Data!$F:$F,port0201!$B$9),3))) -> 57281.96 | K12: =IF(port0201!$B$9="All Routes",IF(port0201!$B$8<>"Tonnage","z",ROUND(SUMIFS(Data!$D:$D,Data!$A:$A,K$5,Data!$C:$C,K$4,Data!$B:$B,$B12),3)),IF(port0201!$B$8<>"Tonnage","z",ROUND(SUMIFS(Data!$D:$D,Data!$A:$A,K$5,Data!$C:$C,K$4,Data!$B:$B,$B12,Data!$F:$F,port0201!$B$9),3))) -> 47426.647 | ... AC12: =IF(port0201!$B$9="All Routes",IF(port0201!$B$8<>"Tonnage","z",ROUND(SUMIFS(Data!$D:$D,Data!$A:$A,AC$5,Data!$C:$C,AC$4,Data!$B:$B,$B12),3)),IF(port0201!$B$8<>"Tonnage","z",ROUND(SUMIFS(Data!$D:$D,Data!$A:$A,AC$5,Data!$C:$C,AC$4,Data!$B:$B,$B12,Data!$F:$F,port0201!$B$9),3))) -> 4358.873 | AE12: =(AC12-AB12)/AB12 -> -0.091159238 | AF12: =AC12-AB12 -> -437.207 | AG12: =(AC11-AB11)/AB11 -> -0.12659719 | AJ12: =AB12-AA12 -> -1923.39 | AK12: =AJ12/AA12 -> -0.28624133
A13: Dry bulk | B13: 23 | C13: Agricultural products | D13: =IF(port0201!$B$9="All Routes",IF(port0201!$B$8<>"Tonnage","z",ROUND(SUMIFS(Data!$D:$D,Data!$A:$A,D$5,Data!$C:$C,D$4,Data!$B:$B,$B13),3)),IF(port0201!$B$8<>"Tonnage","z",ROUND(SUMIFS(Data!$D:$D,Data!$A:$A,D$5,Data!$C:$C,D$4,Data!$B:$B,$B13,Data!$F:$F,port0201!$B$9),3))) -> 14106.536 | E13: =IF(port0201!$B$9="All Routes",IF(port0201!$B$8<>"Tonnage","z",ROUND(SUMIFS(Data!$D:$D,Data!$A:$A,E$5,Data!$C:$C,E$4,Data!$B:$B,$B13),3)),IF(port0201!$B$8<>"Tonnage","z",ROUND(SUMIFS(Data!$D:$D,Data!$A:$A,E$5,Data!$C:$C,E$4,Data!$B:$B,$B13,Data!$F:$F,port0201!$B$9),3))) -> 13026.302 | F13: =IF(port0201!$B$9="All Routes",IF(port0201!$B$8<>"Tonnage","z",ROUND(SUMIFS(Data!$D:$D,Data!$A:$A,F$5,Data!$C:$C,F$4,Data!$B:$B,$B13),3)),IF(port0201!$B$8<>"Tonnage","z",ROUND(SUMIFS(Data!$D:$D,Data!$A:$A,F$5,Data!$C:$C,F$4,Data!$B:$B,$B13,Data!$F:$F,port0201!$B$9),3))) -> 13061.469 | G13: =IF(port0201!$B$9="All Routes",IF(port0201!$B$8<>"Tonnage","z",ROUND(SUMIFS(Data!$D:$D,Data!$A:$A,G$5,Data!$C:$C,G$4,Data!$B:$B,$B13),3)),IF(port0201!$B$8<>"Tonnage","z",ROUND(SUMIFS(Data!$D:$D,Data!$A:$A,G$5,Data!$C:$C,G$4,Data!$B:$B,$B13,Data!$F:$F,port0201!$B$9),3))) -> 14751.974 | H13: =IF(port0201!$B$9="All Routes",IF(port0201!$B$8<>"Tonnage","z",ROUND(SUMIFS(Data!$D:$D,Data!$A:$A,H$5,Data!$C:$C,H$4,Data!$B:$B,$B13),3)),IF(port0201!$B$8<>"Tonnage","z",ROUND(SUMIFS(Data!$D:$D,Data!$A:$A,H$5,Data!$C:$C,H$4,Data!$B:$B,$B13,Data!$F:$F,port0201!$B$9),3))) -> 12924.524 | I13: =IF(port0201!$B$9="All Routes",IF(port0201!$B$8<>"Tonnage","z",ROUND(SUMIFS(Data!$D:$D,Data!$A:$A,I$5,Data!$C:$C,I$4,Data!$B:$B,$B13),3)),IF(port0201!$B$8<>"Tonnage","z",ROUND(SUMIFS(Data!$D:$D,Data!$A:$A,I$5,Data!$C:$C,I$4,Data!$B:$B,$B13,Data!$F:$F,port0201!$B$9),3))) -> 13607.652 | J13: =IF(port0201!$B$9="All Routes",IF(port0201!$B$8<>"Tonnage","z",ROUND(SUMIFS(Data!$D:$D,Data!$A:$A,J$5,Data!$C:$C,J$4,Data!$B:$B,$B13),3)),IF(port0201!$B$8<>"Tonnage","z",ROUND(SUMIFS(Data!$D:$D,Data!$A:$A,J$5,Data!$C:$C,J$4,Data!$B:$B,$B13,Data!$F:$F,port0201!$B$9),3))) -> 13095.04 | K13: =IF(port0201!$B$9="All Routes",IF(port0201!$B$8<>"Tonnage","z",ROUND(SUMIFS(Data!$D:$D,Data!$A:$A,K$5,Data!$C:$C,K$4,Data!$B:$B,$B13),3)),IF(port0201!$B$8<>"Tonnage","z",ROUND(SUMIFS(Data!$D:$D,Data!$A:$A,K$5,Data!$C:$C,K$4,Data!$B:$B,$B13,Data!$F:$F,port0201!$B$9),3))) -> 12745.616 | ... AC13: =IF(port0201!$B$9="All Routes",IF(port0201!$B$8<>"Tonnage","z",ROUND(SUMIFS(Data!$D:$D,Data!$A:$A,AC$5,Data!$C:$C,AC$4,Data!$B:$B,$B13),3)),IF(port0201!$B$8<>"Tonnage","z",ROUND(SUMIFS(Data!$D:$D,Data!$A:$A,AC$5,Data!$C:$C,AC$4,Data!$B:$B,$B13,Data!$F:$F,port0201!$B$9),3))) -> 10888.209 | AE13: =(AC13-AB13)/AB13 -> 0.070109185 | AF13: =AC13-AB13 -> 713.351 | AH13: 47958 | AJ13: =AB13-AA13 -> -662.369 | AK13: =AJ13/AA13 -> -0.061119786
A14: Dry bulk | B14: 24 | C14: Wood pellets | D14: =IF(port0201!$B$9="All Routes",IF(port0201!$B$8<>"Tonnage","z",ROUND(SUMIFS(Data!$D:$D,Data!$A:$A,D$5,Data!$C:$C,D$4,Data!$B:$B,$B14),3)),IF(port0201!$B$8<>"Tonnage","z",ROUND(SUMIFS(Data!$D:$D,Data!$A:$A,D$5,Data!$C:$C,D$4,Data!$B:$B,$B14,Data!$F:$F,port0201!$B$9),3))) -> 0 | E14: =IF(port0201!$B$9="All Routes",IF(port0201!$B$8<>"Tonnage","z",ROUND(SUMIFS(Data!$D:$D,Data!$A:$A,E$5,Data!$C:$C,E$4,Data!$B:$B,$B14),3)),IF(port0201!$B$8<>"Tonnage","z",ROUND(SUMIFS(Data!$D:$D,Data!$A:$A,E$5,Data!$C:$C,E$4,Data!$B:$B,$B14,Data!$F:$F,port0201!$B$9),3))) -> 0 | F14: =IF(port0201!$B$9="All Routes",IF(port0201!$B$8<>"Tonnage","z",ROUND(SUMIFS(Data!$D:$D,Data!$A:$A,F$5,Data!$C:$C,F$4,Data!$B:$B,$B14),3)),IF(port0201!$B$8<>"Tonnage","z",ROUND(SUMIFS(Data!$D:$D,Data!$A:$A,F$5,Data!$C:$C,F$4,Data!$B:$B,$B14,Data!$F:$F,port0201!$B$9),3))) -> 0 | G14: =IF(port0201!$B$9="All Routes",IF(port0201!$B$8<>"Tonnage","z",ROUND(SUMIFS(Data!$D:$D,Data!$A:$A,G$5,Data!$C:$C,G$4,Data!$B:$B,$B14),3)),IF(port0201!$B$8<>"Tonnage","z",ROUND(SUMIFS(Data!$D:$D,Data!$A:$A,G$5,Data!$C:$C,G$4,Data!$B:$B,$B14,Data!$F:$F,port0201!$B$9),3))) -> 0 | H14: =IF(port0201!$B$9="All Routes",IF(port0201!$B$8<>"Tonnage","z",ROUND(SUMIFS(Data!$D:$D,Data!$A:$A,H$5,Data!$C:$C,H$4,Data!$B:$B,$B14),3)),IF(port0201!$B$8<>"Tonnage","z",ROUND(SUMIFS(Data!$D:$D,Data!$A:$A,H$5,Data!$C:$C,H$4,Data!$B:$B,$B14,Data!$F:$F,port0201!$B$9),3))) -> 0 | I14: =IF(port0201!$B$9="All Routes",IF(port0201!$B$8<>"Tonnage","z",ROUND(SUMIFS(Data!$D:$D,Data!$A:$A,I$5,Data!$C:$C,I$4,Data!$B:$B,$B14),3)),IF(port0201!$B$8<>"Tonnage","z",ROUND(SUMIFS(Data!$D:$D,Data!$A:$A,I$5,Data!$C:$C,I$4,Data!$B:$B,$B14,Data!$F:$F,port0201!$B$9),3))) -> 0 | J14: =IF(port0201!$B$9="All Routes",IF(port0201!$B$8<>"Tonnage","z",ROUND(SUMIFS(Data!$D:$D,Data!$A:$A,J$5,Data!$C:$C,J$4,Data!$B:$B,$B14),3)),IF(port0201!$B$8<>"Tonnage","z",ROUND(SUMIFS(Data!$D:$D,Data!$A:$A,J$5,Data!$C:$C,J$4,Data!$B:$B,$B14,Data!$F:$F,port0201!$B$9),3))) -> 0 | K14: =IF(port0201!$B$9="All Routes",IF(port0201!$B$8<>"Tonnage","z",ROUND(SUMIFS(Data!$D:$D,Data!$A:$A,K$5,Data!$C:$C,K$4,Data!$B:$B,$B14),3)),IF(port0201!$B$8<>"Tonnage","z",ROUND(SUMIFS(Data!$D:$D,Data!$A:$A,K$5,Data!$C:$C,K$4,Data!$B:$B,$B14,Data!$F:$F,port0201!$B$9),3))) -> 0 | ... AC14: =IF(port0201!$B$9="All Routes",IF(port0201!$B$8<>"Tonnage","z",ROUND(SUMIFS(Data!$D:$D,Data!$A:$A,AC$5,Data!$C:$C,AC$4,Data!$B:$B,$B14),3)),IF(port0201!$B$8<>"Tonnage","z",ROUND(SUMIFS(Data!$D:$D,Data!$A:$A,AC$5,Data!$C:$C,AC$4,Data!$B:$B,$B14,Data!$F:$F,port0201!$B$9),3))) -> 9935.277 | AE14: =(AC14-AB14)/AB14 -> #DIV/0! | AF14: =AC14-AB14 -> 9935.277 | AG14: =AC14+AC15 -> 53525.148 | AJ14: =AB14-AA14 -> 0 | AK14: =AJ14/AA14 -> #DIV/0!
A15: Dry bulk | B15: 29 | C15: Other dry bulk | D15: =IF(port0201!$B$9="All Routes",IF(port0201!$B$8<>"Tonnage","z",ROUND(SUMIFS(Data!$D:$D,Data!$A:$A,D$5,Data!$C:$C,D$4,Data!$B:$B,$B15),3)),IF(port0201!$B$8<>"Tonnage","z",ROUND(SUMIFS(Data!$D:$D,Data!$A:$A,D$5,Data!$C:$C,D$4,Data!$B:$B,$B15,Data!$F:$F,port0201!$B$9),3))) -> 41347.061 | E15: =IF(port0201!$B$9="All Routes",IF(port0201!$B$8<>"Tonnage","z",ROUND(SUMIFS(Data!$D:$D,Data!$A:$A,E$5,Data!$C:$C,E$4,Data!$B:$B,$B15),3)),IF(port0201!$B$8<>"Tonnage","z",ROUND(SUMIFS(Data!$D:$D,Data!$A:$A,E$5,Data!$C:$C,E$4,Data!$B:$B,$B15,Data!$F:$F,port0201!$B$9),3))) -> 42480.347 | F15: =IF(port0201!$B$9="All Routes",IF(port0201!$B$8<>"Tonnage","z",ROUND(SUMIFS(Data!$D:$D,Data!$A:$A,F$5,Data!$C:$C,F$4,Data!$B:$B,$B15),3)),IF(port0201!$B$8<>"Tonnage","z",ROUND(SUMIFS(Data!$D:$D,Data!$A:$A,F$5,Data!$C:$C,F$4,Data!$B:$B,$B15,Data!$F:$F,port0201!$B$9),3))) -> 43673.663 | G15: =IF(port0201!$B$9="All Routes",IF(port0201!$B$8<>"Tonnage","z",ROUND(SUMIFS(Data!$D:$D,Data!$A:$A,G$5,Data!$C:$C,G$4,Data!$B:$B,$B15),3)),IF(port0201!$B$8<>"Tonnage","z",ROUND(SUMIFS(Data!$D:$D,Data!$A:$A,G$5,Data!$C:$C,G$4,Data!$B:$B,$B15,Data!$F:$F,port0201!$B$9),3))) -> 44407.473 | H15: =IF(port0201!$B$9="All Routes",IF(port0201!$B$8<>"Tonnage","z",ROUND(SUMIFS(Data!$D:$D,Data!$A:$A,H$5,Data!$C:$C,H$4,Data!$B:$B,$B15),3)),IF(port0201!$B$8<>"Tonnage","z",ROUND(SUMIFS(Data!$D:$D,Data!$A:$A,H$5,Data!$C:$C,H$4,Data!$B:$B,$B15,Data!$F:$F,port0201!$B$9),3))) -> 42122.459 | I15: =IF(port0201!$B$9="All Routes",IF(port0201!$B$8<>"Tonnage","z",ROUND(SUMIFS(Data!$D:$D,Data!$A:$A,I$5,Data!$C:$C,I$4,Data!$B:$B,$B15),3)),IF(port0201!$B$8<>"Tonnage","z",ROUND(SUMIFS(Data!$D:$D,Data!$A:$A,I$5,Data!$C:$C,I$4,Data!$B:$B,$B15,Data!$F:$F,port0201!$B$9),3))) -> 42232.211 | J15: =IF(port0201!$B$9="All Routes",IF(port0201!$B$8<>"Tonnage","z",ROUND(SUMIFS(Data!$D:$D,Data!$A:$A,J$5,Data!$C:$C,J$4,Data!$B:$B,$B15),3)),IF(port0201!$B$8<>"Tonnage","z",ROUND(SUMIFS(Data!$D:$D,Data!$A:$A,J$5,Data!$C:$C,J$4,Data!$B:$B,$B15,Data!$F:$F,port0201!$B$9),3))) -> 44402.503 | K15: =IF(port0201!$B$9="All Routes",IF(port0201!$B$8<>"Tonnage","z",ROUND(SUMIFS(Data!$D:$D,Data!$A:$A,K$5,Data!$C:$C,K$4,Data!$B:$B,$B15),3)),IF(port0201!$B$8<>"Tonnage","z",ROUND(SUMIFS(Data!$D:$D,Data!$A:$A,K$5,Data!$C:$C,K$4,Data!$B:$B,$B15,Data!$F:$F,port0201!$B$9),3))) -> 46066.558 | ... AC15: =IF(port0201!$B$9="All Routes",IF(port0201!$B$8<>"Tonnage","z",ROUND(SUMIFS(Data!$D:$D,Data!$A:$A,AC$5,Data!$C:$C,AC$4,Data!$B:$B,$B15),3)),IF(port0201!$B$8<>"Tonnage","z",ROUND(SUMIFS(Data!$D:$D,Data!$A:$A,AC$5,Data!$C:$C,AC$4,Data!$B:$B,$B15,Data!$F:$F,port0201!$B$9),3))) -> 43589.871 | AE15: =(AC15-AB15)/AB15 -> -0.2011353 | AF15: =AC15-AB15 -> -10974.902 | AH15: 43484 | AJ15: =AB15-AA15 -> 977.338 | AK15: =AJ15/AA15 -> 0.018238193
A16: Dry bulk | B16: All Dry Bulk | C16: All Routes dry bulk traffic | D16: =IF(port0201!$B$8<>"Tonnage","z",ROUND(SUM(D11:D15),3)) -> 103602.5 | E16: =IF(port0201!$B$8<>"Tonnage","z",ROUND(SUM(E11:E15),3)) -> 114986.24 | F16: =IF(port0201!$B$8<>"Tonnage","z",ROUND(SUM(F11:F15),3)) -> 106742.4 | G16: =IF(port0201!$B$8<>"Tonnage","z",ROUND(SUM(G11:G15),3)) -> 114428.96 | H16: =IF(port0201!$B$8<>"Tonnage","z",ROUND(SUM(H11:H15),3)) -> 114189.56 | I16: =IF(port0201!$B$8<>"Tonnage","z",ROUND(SUM(I11:I15),3)) -> 125567.74 | J16: =IF(port0201!$B$8<>"Tonnage","z",ROUND(SUM(J11:J15),3)) -> 133080.01 | K16: =IF(port0201!$B$8<>"Tonnage","z",ROUND(SUM(K11:K15),3)) -> 125383.1 | ... AC16: =IF(port0201!$B$8<>"Tonnage","z",ROUND(SUM(AC11:AC15),3)) -> 78735.887 | AD16: =SUM(AB11:AB15)-AB16 -> 0 | AE16: =(AC16-AB16)/AB16 -> -0.027274359 | AF16: =AC16-AB16 -> -2207.684 | AH16: =AC15+AC14 -> 53525.148 | AJ16: =AB16-AA16 -> -3466.002 | AK16: =AJ16/AA16 -> -0.041061717
A17: Container traffic | B17: 31 | C17: 20' containers | D17: =IF(D$3="All Routes", IF($G$2="Tonnage",SUMIFS(Data!$D:$D,Data!$A:$A,Working!D$5,Data!$B:$B,Working!$B17,Data!$C:$C,Working!D$4), IF($G$2="Units",SUMIFS(Data!$E:$E,Data!$A:$A,Working!D$5,Data!$B:$B,Working!$B17,Data!$C:$C,Working!D$4),SUMIFS(Data!$G:$G,Data!$A:$A,Working!D$5,Data!$B:$B,Working!$B17,Data!$C:$C,Working!D$4))), IF($G$2="Tonnage",SUMIFS(Data!$D:$D,Data!$A:$A,Working!D$5,Data!$B:$B,Working!$B17,Data!$C:$C,Working!D$4,Data!$F:$F,Working!D$3), IF($G$2="Units",SUMIFS(Data!$E:$E,Data!$A:$A,Working!D$5,Data!$B:$B,Working!$B17,Data!$C:$C,Working!D$4,Data!$F:$F,Working!D$3),SUMIFS(Data!$G:$G,Data!$A:$A,Working!D$5,Data!$B:$B,Working!$B17,Data!$C:$C,Working!D$4,Data!$F:$F,Working!D$3)))) -> 23042.378 | E17: =IF(E$3="All Routes", IF($G$2="Tonnage",SUMIFS(Data!$D:$D,Data!$A:$A,Working!E$5,Data!$B:$B,Working!$B17,Data!$C:$C,Working!E$4), IF($G$2="Units",SUMIFS(Data!$E:$E,Data!$A:$A,Working!E$5,Data!$B:$B,Working!$B17,Data!$C:$C,Working!E$4),SUMIFS(Data!$G:$G,Data!$A:$A,Working!E$5,Data!$B:$B,Working!$B17,Data!$C:$C,Working!E$4))), IF($G$2="Tonnage",SUMIFS(Data!$D:$D,Data!$A:$A,Working!E$5,Data!$B:$B,Working!$B17,Data!$C:$C,Working!E$4,Data!$F:$F,Working!E$3), IF($G$2="Units",SUMIFS(Data!$E:$E,Data!$A:$A,Working!E$5,Data!$B:$B,Working!$B17,Data!$C:$C,Working!E$4,Data!$F:$F,Working!E$3),SUMIFS(Data!$G:$G,Data!$A:$A,Working!E$5,Data!$B:$B,Working!$B17,Data!$C:$C,Working!E$4,Data!$F:$F,Working!E$3)))) -> 22156.339 | F17: =IF(F$3="All Routes", IF($G$2="Tonnage",SUMIFS(Data!$D:$D,Data!$A:$A,Working!F$5,Data!$B:$B,Working!$B17,Data!$C:$C,Working!F$4), IF($G$2="Units",SUMIFS(Data!$E:$E,Data!$A:$A,Working!F$5,Data!$B:$B,Working!$B17,Data!$C:$C,Working!F$4),SUMIFS(Data!$G:$G,Data!$A:$A,Working!F$5,Data!$B:$B,Working!$B17,Data!$C:$C,Working!F$4))), IF($G$2="Tonnage",SUMIFS(Data!$D:$D,Data!$A:$A,Working!F$5,Data!$B:$B,Working!$B17,Data!$C:$C,Working!F$4,Data!$F:$F,Working!F$3), IF($G$2="Units",SUMIFS(Data!$E:$E,Data!$A:$A,Working!F$5,Data!$B:$B,Working!$B17,Data!$C:$C,Working!F$4,Data!$F:$F,Working!F$3),SUMIFS(Data!$G:$G,Data!$A:$A,Working!F$5,Data!$B:$B,Working!$B17,Data!$C:$C,Working!F$4,Data!$F:$F,Working!F$3)))) -> 19900.424 | G17: =IF(G$3="All Routes", IF($G$2="Tonnage",SUMIFS(Data!$D:$D,Data!$A:$A,Working!G$5,Data!$B:$B,Working!$B17,Data!$C:$C,Working!G$4), IF($G$2="Units",SUMIFS(Data!$E:$E,Data!$A:$A,Working!G$5,Data!$B:$B,Working!$B17,Data!$C:$C,Working!G$4),SUMIFS(Data!$G:$G,Data!$A:$A,Working!G$5,Data!$B:$B,Working!$B17,Data!$C:$C,Working!G$4))), IF($G$2="Tonnage",SUMIFS(Data!$D:$D,Data!$A:$A,Working!G$5,Data!$B:$B,Working!$B17,Data!$C:$C,Working!G$4,Data!$F:$F,Working!G$3), IF($G$2="Units",SUMIFS(Data!$E:$E,Data!$A:$A,Working!G$5,Data!$B:$B,Working!$B17,Data!$C:$C,Working!G$4,Data!$F:$F,Working!G$3),SUMIFS(Data!$G:$G,Data!$A:$A,Working!G$5,Data!$B:$B,Working!$B17,Data!$C:$C,Working!G$4,Data!$F:$F,Working!G$3)))) -> 19855.484 | H17: =IF(H$3="All Routes", IF($G$2="Tonnage",SUMIFS(Data!$D:$D,Data!$A:$A,Working!H$5,Data!$B:$B,Working!$B17,Data!$C:$C,Working!H$4), IF($G$2="Units",SUMIFS(Data!$E:$E,Data!$A:$A,Working!H$5,Data!$B:$B,Working!$B17,Data!$C:$C,Working!H$4),SUMIFS(Data!$G:$G,Data!$A:$A,Working!H$5,Data!$B:$B,Working!$B17,Data!$C:$C,Working!H$4))), IF($G$2="Tonnage",SUMIFS(Data!$D:$D,Data!$A:$A,Working!H$5,Data!$B:$B,Working!$B17,Data!$C:$C,Working!H$4,Data!$F:$F,Working!H$3), IF($G$2="Units",SUMIFS(Data!$E:$E,Data!$A:$A,Working!H$5,Data!$B:$B,Working!$B17,Data!$C:$C,Working!H$4,Data!$F:$F,Working!H$3),SUMIFS(Data!$G:$G,Data!$A:$A,Working!H$5,Data!$B:$B,Working!$B17,Data!$C:$C,Working!H$4,Data!$F:$F,Working!H$3)))) -> 21013.069 | I17: =IF(I$3="All Routes", IF($G$2="Tonnage",SUMIFS(Data!$D:$D,Data!$A:$A,Working!I$5,Data!$B:$B,Working!$B17,Data!$C:$C,Working!I$4), IF($G$2="Units",SUMIFS(Data!$E:$E,Data!$A:$A,Working!I$5,Data!$B:$B,Working!$B17,Data!$C:$C,Working!I$4),SUMIFS(Data!$G:$G,Data!$A:$A,Working!I$5,Data!$B:$B,Working!$B17,Data!$C:$C,Working!I$4))), IF($G$2="Tonnage",SUMIFS(Data!$D:$D,Data!$A:$A,Working!I$5,Data!$B:$B,Working!$B17,Data!$C:$C,Working!I$4,Data!$F:$F,Working!I$3), IF($G$2="Units",SUMIFS(Data!$E:$E,Data!$A:$A,Working!I$5,Data!$B:$B,Working!$B17,Data!$C:$C,Working!I$4,Data!$F:$F,Working!I$3),SUMIFS(Data!$G:$G,Data!$A:$A,Working!I$5,Data!$B:$B,Working!$B17,Data!$C:$C,Working!I$4,Data!$F:$F,Working!I$3)))) -> 19678.151 | J17: =IF(J$3="All Routes", IF($G$2="Tonnage",SUMIFS(Data!$D:$D,Data!$A:$A,Working!J$5,Data!$B:$B,Working!$B17,Data!$C:$C,Working!J$4), IF($G$2="Units",SUMIFS(Data!$E:$E,Data!$A:$A,Working!J$5,Data!$B:$B,Working!$B17,Data!$C:$C,Working!J$4),SUMIFS(Data!$G:$G,Data!$A:$A,Working!J$5,Data!$B:$B,Working!$B17,Data!$C:$C,Working!J$4))), IF($G$2="Tonnage",SUMIFS(Data!$D:$D,Data!$A:$A,Working!J$5,Data!$B:$B,Working!$B17,Data!$C:$C,Working!J$4,Data!$F:$F,Working!J$3), IF($G$2="Units",SUMIFS(Data!$E:$E,Data!$A:$A,Working!J$5,Data!$B:$B,Working!$B17,Data!$C:$C,Working!J$4,Data!$F:$F,Working!J$3),SUMIFS(Data!$G:$G,Data!$A:$A,Working!J$5,Data!$B:$B,Working!$B17,Data!$C:$C,Working!J$4,Data!$F:$F,Working!J$3)))) -> 18547.524 | K17: =IF(K$3="All Routes", IF($G$2="Tonnage",SUMIFS(Data!$D:$D,Data!$A:$A,Working!K$5,Data!$B:$B,Working!$B17,Data!$C:$C,Working!K$4), IF($G$2="Units",SUMIFS(Data!$E:$E,Data!$A:$A,Working!K$5,Data!$B:$B,Working!$B17,Data!$C:$C,Working!K$4),SUMIFS(Data!$G:$G,Data!$A:$A,Working!K$5,Data!$B:$B,Working!$B17,Data!$C:$C,Working!K$4))), IF($G$2="Tonnage",SUMIFS(Data!$D:$D,Data!$A:$A,Working!K$5,Data!$B:$B,Working!$B17,Data!$C:$C,Working!K$4,Data!$F:$F,Working!K$3), IF($G$2="Units",SUMIFS(Data!$E:$E,Data!$A:$A,Working!K$5,Data!$B:$B,Working!$B17,Data!$C:$C,Working!K$4,Data!$F:$F,Working!K$3),SUMIFS(Data!$G:$G,Data!$A:$A,Working!K$5,Data!$B:$B,Working!$B17,Data!$C:$C,Working!K$4,Data!$F:$F,Working!K$3)))) -> 19087.891 | ... AC17: =IF(AC$3="All Routes", IF($G$2="Tonnage",SUMIFS(Data!$D:$D,Data!$A:$A,Working!AC$5,Data!$B:$B,Working!$B17,Data!$C:$C,Working!AC$4), IF($G$2="Units",SUMIFS(Data!$E:$E,Data!$A:$A,Working!AC$5,Data!$B:$B,Working!$B17,Data!$C:$C,Working!AC$4),SUMIFS(Data!$G:$G,Data!$A:$A,Working!AC$5,Data!$B:$B,Working!$B17,Data!$C:$C,Working!AC$4))), IF($G$2="Tonnage",SUMIFS(Data!$D:$D,Data!$A:$A,Working!AC$5,Data!$B:$B,Working!$B17,Data!$C:$C,Working!AC$4,Data!$F:$F,Working!AC$3), IF($G$2="Units",SUMIFS(Data!$E:$E,Data!$A:$A,Working!AC$5,Data!$B:$B,Working!$B17,Data!$C:$C,Working!AC$4,Data!$F:$F,Working!AC$3),SUMIFS(Data!$G:$G,Data!$A:$A,Working!AC$5,Data!$B:$B,Working!$B17,Data!$C:$C,Working!AC$4,Data!$F:$F,Working!AC$3)))) -> 17760.956 | AE17: =(AC17-AB17)/AB17 -> 0.10748259 | AF17: =AC17-AB17 -> 1723.7233 | AH17: =(AH16-AB15)/AB15 -> -0.019053044 | AJ17: =AB17-AA17 -> -529.378 | AK17: =AJ17/AA17 -> -0.031954514
A18: Container traffic | B18: 32 | C18: 40' containers | D18: =IF(D$3="All Routes", IF($G$2="Tonnage",SUMIFS(Data!$D:$D,Data!$A:$A,Working!D$5,Data!$B:$B,Working!$B18,Data!$C:$C,Working!D$4), IF($G$2="Units",SUMIFS(Data!$E:$E,Data!$A:$A,Working!D$5,Data!$B:$B,Working!$B18,Data!$C:$C,Working!D$4),SUMIFS(Data!$G:$G,Data!$A:$A,Working!D$5,Data!$B:$B,Working!$B18,Data!$C:$C,Working!D$4))), IF($G$2="Tonnage",SUMIFS(Data!$D:$D,Data!$A:$A,Working!D$5,Data!$B:$B,Working!$B18,Data!$C:$C,Working!D$4,Data!$F:$F,Working!D$3), IF($G$2="Units",SUMIFS(Data!$E:$E,Data!$A:$A,Working!D$5,Data!$B:$B,Working!$B18,Data!$C:$C,Working!D$4,Data!$F:$F,Working!D$3),SUMIFS(Data!$G:$G,Data!$A:$A,Working!D$5,Data!$B:$B,Working!$B18,Data!$C:$C,Working!D$4,Data!$F:$F,Working!D$3)))) -> 26471.084 | E18: =IF(E$3="All Routes", IF($G$2="Tonnage",SUMIFS(Data!$D:$D,Data!$A:$A,Working!E$5,Data!$B:$B,Working!$B18,Data!$C:$C,Working!E$4), IF($G$2="Units",SUMIFS(Data!$E:$E,Data!$A:$A,Working!E$5,Data!$B:$B,Working!$B18,Data!$C:$C,Working!E$4),SUMIFS(Data!$G:$G,Data!$A:$A,Working!E$5,Data!$B:$B,Working!$B18,Data!$C:$C,Working!E$4))), IF($G$2="Tonnage",SUMIFS(Data!$D:$D,Data!$A:$A,Working!E$5,Data!$B:$B,Working!$B18,Data!$C:$C,Working!E$4,Data!$F:$F,Working!E$3), IF($G$2="Units",SUMIFS(Data!$E:$E,Data!$A:$A,Working!E$5,Data!$B:$B,Working!$B18,Data!$C:$C,Working!E$4,Data!$F:$F,Working!E$3),SUMIFS(Data!$G:$G,Data!$A:$A,Working!E$5,Data!$B:$B,Working!$B18,Data!$C:$C,Working!E$4,Data!$F:$F,Working!E$3)))) -> 26227.638 | F18: =IF(F$3="All Routes", IF($G$2="Tonnage",SUMIFS(Data!$D:$D,Data!$A:$A,Working!F$5,Data!$B:$B,Working!$B18,Data!$C:$C,Working!F$4), IF($G$2="Units",SUMIFS(Data!$E:$E,Data!$A:$A,Working!F$5,Data!$B:$B,Working!$B18,Data!$C:$C,Working!F$4),SUMIFS(Data!$G:$G,Data!$A:$A,Working!F$5,Data!$B:$B,Working!$B18,Data!$C:$C,Working!F$4))), IF($G$2="Tonnage",SUMIFS(Data!$D:$D,Data!$A:$A,Working!F$5,Data!$B:$B,Working!$B18,Data!$C:$C,Working!F$4,Data!$F:$F,Working!F$3), IF($G$2="Units",SUMIFS(Data!$E:$E,Data!$A:$A,Working!F$5,Data!$B:$B,Working!$B18,Data!$C:$C,Working!F$4,Data!$F:$F,Working!F$3),SUMIFS(Data!$G:$G,Data!$A:$A,Working!F$5,Data!$B:$B,Working!$B18,Data!$C:$C,Working!F$4,Data!$F:$F,Working!F$3)))) -> 26765.706 | G18: =IF(G$3="All Routes", IF($G$2="Tonnage",SUMIFS(Data!$D:$D,Data!$A:$A,Working!G$5,Data!$B:$B,Working!$B18,Data!$C:$C,Working!G$4), IF($G$2="Units",SUMIFS(Data!$E:$E,Data!$A:$A,Working!G$5,Data!$B:$B,Working!$B18,Data!$C:$C,Working!G$4),SUMIFS(Data!$G:$G,Data!$A:$A,Working!G$5,Data!$B:$B,Working!$B18,Data!$C:$C,Working!G$4))), IF($G$2="Tonnage",SUMIFS(Data!$D:$D,Data!$A:$A,Working!G$5,Data!$B:$B,Working!$B18,Data!$C:$C,Working!G$4,Data!$F:$F,Working!G$3), IF($G$2="Units",SUMIFS(Data!$E:$E,Data!$A:$A,Working!G$5,Data!$B:$B,Working!$B18,Data!$C:$C,Working!G$4,Data!$F:$F,Working!G$3),SUMIFS(Data!$G:$G,Data!$A:$A,Working!G$5,Data!$B:$B,Working!$B18,Data!$C:$C,Working!G$4,Data!$F:$F,Working!G$3)))) -> 25700.436 | H18: =IF(H$3="All Routes", IF($G$2="Tonnage",SUMIFS(Data!$D:$D,Data!$A:$A,Working!H$5,Data!$B:$B,Working!$B18,Data!$C:$C,Working!H$4), IF($G$2="Units",SUMIFS(Data!$E:$E,Data!$A:$A,Working!H$5,Data!$B:$B,Working!$B18,Data!$C:$C,Working!H$4),SUMIFS(Data!$G:$G,Data!$A:$A,Working!H$5,Data!$B:$B,Working!$B18,Data!$C:$C,Working!H$4))), IF($G$2="Tonnage",SUMIFS(Data!$D:$D,Data!$A:$A,Working!H$5,Data!$B:$B,Working!$B18,Data!$C:$C,Working!H$4,Data!$F:$F,Working!H$3), IF($G$2="Units",SUMIFS(Data!$E:$E,Data!$A:$A,Working!H$5,Data!$B:$B,Working!$B18,Data!$C:$C,Working!H$4,Data!$F:$F,Working!H$3),SUMIFS(Data!$G:$G,Data!$A:$A,Working!H$5,Data!$B:$B,Working!$B18,Data!$C:$C,Working!H$4,Data!$F:$F,Working!H$3)))) -> 30244.413 | I18: =IF(I$3="All Routes", IF($G$2="Tonnage",SUMIFS(Data!$D:$D,Data!$A:$A,Working!I$5,Data!$B:$B,Working!$B18,Data!$C:$C,Working!I$4), IF($G$2="Units",SUMIFS(Data!$E:$E,Data!$A:$A,Working!I$5,Data!$B:$B,Working!$B18,Data!$C:$C,Working!I$4),SUMIFS(Data!$G:$G,Data!$A:$A,Working!I$5,Data!$B:$B,Working!$B18,Data!$C:$C,Working!I$4))), IF($G$2="Tonnage",SUMIFS(Data!$D:$D,Data!$A:$A,Working!I$5,Data!$B:$B,Working!$B18,Data!$C:$C,Working!I$4,Data!$F:$F,Working!I$3), IF($G$2="Units",SUMIFS(Data!$E:$E,Data!$A:$A,Working!I$5,Data!$B:$B,Working!$B18,Data!$C:$C,Working!I$4,Data!$F:$F,Working!I$3),SUMIFS(Data!$G:$G,Data!$A:$A,Working!I$5,Data!$B:$B,Working!$B18,Data!$C:$C,Working!I$4,Data!$F:$F,Working!I$3)))) -> 30082.465 | J18: =IF(J$3="All Routes", IF($G$2="Tonnage",SUMIFS(Data!$D:$D,Data!$A:$A,Working!J$5,Data!$B:$B,Working!$B18,Data!$C:$C,Working!J$4), IF($G$2="Units",SUMIFS(Data!$E:$E,Data!$A:$A,Working!J$5,Data!$B:$B,Working!$B18,Data!$C:$C,Working!J$4),SUMIFS(Data!$G:$G,Data!$A:$A,Working!J$5,Data!$B:$B,Working!$B18,Data!$C:$C,Working!J$4))), IF($G$2="Tonnage",SUMIFS(Data!$D:$D,Data!$A:$A,Working!J$5,Data!$B:$B,Working!$B18,Data!$C:$C,Working!J$4,Data!$F:$F,Working!J$3), IF($G$2="Units",SUMIFS(Data!$E:$E,Data!$A:$A,Working!J$5,Data!$B:$B,Working!$B18,Data!$C:$C,Working!J$4,Data!$F:$F,Working!J$3),SUMIFS(Data!$G:$G,Data!$A:$A,Working!J$5,Data!$B:$B,Working!$B18,Data!$C:$C,Working!J$4,Data!$F:$F,Working!J$3)))) -> 31773.799 | K18: =IF(K$3="All Routes", IF($G$2="Tonnage",SUMIFS(Data!$D:$D,Data!$A:$A,Working!K$5,Data!$B:$B,Working!$B18,Data!$C:$C,Working!K$4), IF($G$2="Units",SUMIFS(Data!$E:$E,Data!$A:$A,Working!K$5,Data!$B:$B,Working!$B18,Data!$C:$C,Working!K$4),SUMIFS(Data!$G:$G,Data!$A:$A,Working!K$5,Data!$B:$B,Working!$B18,Data!$C:$C,Working!K$4))), IF($G$2="Tonnage",SUMIFS(Data!$D:$D,Data!$A:$A,Working!K$5,Data!$B:$B,Working!$B18,Data!$C:$C,Working!K$4,Data!$F:$F,Working!K$3), IF($G$2="Units",SUMIFS(Data!$E:$E,Data!$A:$A,Working!K$5,Data!$B:$B,Working!$B18,Data!$C:$C,Working!K$4,Data!$F:$F,Working!K$3),SUMIFS(Data!$G:$G,Data!$A:$A,Working!K$5,Data!$B:$B,Working!$B18,Data!$C:$C,Working!K$4,Data!$F:$F,Working!K$3)))) -> 34792.939 | ... AC18: =IF(AC$3="All Routes", IF($G$2="Tonnage",SUMIFS(Data!$D:$D,Data!$A:$A,Working!AC$5,Data!$B:$B,Working!$B18,Data!$C:$C,Working!AC$4), IF($G$2="Units",SUMIFS(Data!$E:$E,Data!$A:$A,Working!AC$5,Data!$B:$B,Working!$B18,Data!$C:$C,Working!AC$4),SUMIFS(Data!$G:$G,Data!$A:$A,Working!AC$5,Data!$B:$B,Working!$B18,Data!$C:$C,Working!AC$4))), IF($G$2="Tonnage",SUMIFS(Data!$D:$D,Data!$A:$A,Working!AC$5,Data!$B:$B,Working!$B18,Data!$C:$C,Working!AC$4,Data!$F:$F,Working!AC$3), IF($G$2="Units",SUMIFS(Data!$E:$E,Data!$A:$A,Working!AC$5,Data!$B:$B,Working!$B18,Data!$C:$C,Working!AC$4,Data!$F:$F,Working!AC$3),SUMIFS(Data!$G:$G,Data!$A:$A,Working!AC$5,Data!$B:$B,Working!$B18,Data!$C:$C,Working!AC$4,Data!$F:$F,Working!AC$3)))) -> 42575.665 | AE18: =(AC18-AB18)/AB18 -> 0.099099942 | AF18: =AC18-AB18 -> 3838.8192 | AJ18: =AB18-AA18 -> 2557.707 | AK18: =AJ18/AA18 -> 0.070695629
